Workbook
Name N1360BZ1: NEW!$N$1361
Name U156B22: 'Export Lines'!$U$1562
Name C1348C2: NEW!$C$1349

Sheet NEW
A1: Order Number | B1: Column 2 | C1: Customer Info | D1: Type | E1: PU / DROP | F1: Production Deadline | G1: Delivery Date | H1: Delivery Conf. | I1: PU / DROP Confirmed | J1: METAL | K1: POWDER COAT | L1: DEKTON | M1: CUSHIONS | N1: CORTE | O1: SEW | P1: FILLING | Q1: FABRIC | R1: FOAM | S1: QTY CUSH | T1: QTY METAL | U1: QTY DEKT | V1: Proj. Hrs Cushion | W1: Proj. Hrs Metal | X1: Proj. Hrs Dekton | Y1: Covers | Z1: Umbrella | AA1: Tenjam/Others | AB1: Firepit System | AC1: Delivery Address | AD1: Column 30
A2: 1572 | B2: ORDER COMPLETED | C2: BETH COHEN | D2: RESIDENTIAL | F2: 46203 | G2: 46204 | H2: YES | J2: COMPLETED | K2: COMPLETED | L2: COMPLETED | M2: COMPLETED | N2: COMPLETED | O2: COMPLETED | P2: COMPLETED | Q2: RECEIVED | R2: RECEIVED | S2: 4 | U2: 1 | Y2: NOT REQUIRED | Z2: NOT REQUIRED | AA2: NOT REQUIRED | AB2: NOT REQUIRED | AC2: 10604 Arista Ln, Fountain Hills, AZ 85268, USA
A3: 1591 | B3: ORDER COMPLETED | C3: BRIAN BEVERLY BUFFINI | D3: RESIDENTIAL | F3: 46203 | G3: 46204 | H3: YES | J3: COMPLETED | K3: COMPLETED | L3: COMPLETED | M3: COMPLETED | N3: COMPLETED | O3: COMPLETED | P3: COMPLETED | Q3: RECEIVED | R3: RECEIVED | S3: 13 | U3: 6 | Y3: NOT REQUIRED | Z3: RECEIVED | AA3: NOT REQUIRED | AB3: NOT REQUIRED | AC3: CALIFORNIA
A4: 1593 | B4: ORDER COMPLETED | C4: JENNIFER LAABS | D4: RESIDENTIAL | F4: 46203 | G4: 46205 | H4: YES | J4: COMPLETED | K4: COMPLETED | L4: COMPLETED | M4: COMPLETED | N4: COMPLETED | O4: COMPLETED | P4: COMPLETED | Q4: RECEIVED | R4: RECEIVED | S4: 16 | U4: 6 | Y4: NOT REQUIRED | Z4: RECEIVED | AA4: NOT REQUIRED | AB4: RECEIVED | AC4: 484 Halcyon Pl, Bethel Island, CA 94511
A5: 1598 | B5: ORDER COMPLETED | C5: WARR-DAN MAYNARD | D5: WARRANTY | E5: 46203 | F5: 46203 | G5: 46203 | J5: NOT REQUIRED | K5: NOT REQUIRED | L5: NOT REQUIRED | M5: COMPLETED | N5: COMPLETED | O5: COMPLETED | P5: COMPLETED | Q5: RECEIVED | R5: SAME-NEED | S5: 25 | T5: 0 | U5: 0 | Y5: NOT REQUIRED | Z5: NOT REQUIRED | AA5: NOT REQUIRED | AB5: NOT REQUIRED | AC5: 20408 E Cloud Rd, Queen Creek, AZ 85142, USA
A6: 1622 | B6: ORDER COMPLETED | C6: MADONA KAKISH | D6: SERVICE | F6: 46203 | G6: 46205 | H6: YES | J6: NOT REQUIRED | K6: NOT REQUIRED | L6: NOT REQUIRED | M6: COMPLETED | N6: COMPLETED | O6: COMPLETED | P6: COMPLETED | Q6: RECEIVED | R6: NOT REQUIRED | S6: 1 | U6: 0 | Y6: NOT REQUIRED | Z6: NOT REQUIRED | AA6: NOT REQUIRED | AB6: NOT REQUIRED | AC6: CALIFORNIA
A7: 1639 | B7: READY FOR DELIVERY | C7: ROBYN LAUKIE-CHRIS PARK | D7: SERVICE-WARRANT | F7: 46204 | G7: 46204 | H7: NO | I7: NA | J7: COMPLETED | K7: COMPLETED | L7: COMPLETED | M7: COMPLETED | N7: COMPLETED | O7: COMPLETED | P7: COMPLETED | Q7: RECEIVED | R7: RECEIVED | S7: 1 | T7: 1 | U7: 1 | X7: 0 | Y7: NOT REQUIRED | Z7: NOT REQUIRED | AA7: NOT REQUIRED | AB7: NOT REQUIRED | AC7: 6352 Arroyo Rd, Cave Creek, AZ 85331, USA
A8: 1677 | B8: READY FOR DELIVERY | C8: TONY KURTH | D8: PICKUP | F8: 46204 | G8: 46204 | H8: NO | I8: NA | J8: NOT REQUIRED | K8: NOT REQUIRED | L8: NOT REQUIRED | M8: NOT REQUIRED | N8: NOT REQUIRED | O8: NOT REQUIRED | P8: NOT REQUIRED | Q8: NOT REQUIRED | R8: NOT REQUIRED | S8: 0 | T8: 0 | U8: 0 | V8: 0 | W8: 0 | X8: 0 | Y8: NOT REQUIRED | Z8: NOT REQUIRED | AA8: NOT REQUIRED | AB8: NOT REQUIRED | AC8: PICKUP
A9: 1688 | B9: NEW | C9: ERIC WHITTAKER | D9: COVERS | F9: 46204 | G9: 46204 | H9: NO | I9: NA | J9: NOT REQUIRED | K9: NOT REQUIRED | L9: NOT REQUIRED | M9: NOT REQUIRED | N9: NOT REQUIRED | O9: NOT REQUIRED | P9: NOT REQUIRED | Q9: NOT REQUIRED | R9: NOT REQUIRED | S9: 0 | T9: 0 | U9: 0 | V9: 0 | W9: 0 | X9: 0 | Y9: ORDERED | Z9: NOT REQUIRED | AA9: NOT REQUIRED | AB9: NOT REQUIRED | AC9: 5400 E Valle Vista Rd #6, Phoenix, AZ 85018
A10: 1715 | B10: ORDER COMPLETED | C10: JAIME KIM LIMBER | D10: SERVICE-WARRANT | E10: 46246 | F10: 46204 | G10: 46246 | H10: YES | I10: YES | J10: COMPLETED | K10: NOT REQUIRED | L10: NOT REQUIRED | M10: NOT REQUIRED | N10: NOT REQUIRED | O10: NOT REQUIRED | P10: NOT REQUIRED | Q10: NOT REQUIRED | R10: NOT REQUIRED | S10: 0 | T10: 2 | U10: 0 | V10: 0 | Y10: NOT REQUIRED | Z10: NOT REQUIRED | AA10: NOT REQUIRED | AB10: NOT REQUIRED | AC10: 4202 N 58th St PHOENIX AZ 85018
A11: 1627 | B11: ORDER COMPLETED | C11: BRITTANY MCDOWELL | D11: RESIDENTIAL | E11: 46233 | F11: 46204 | G11: 46204 | H11: YES | I11: YES | J11: NOT REQUIRED | K11: NOT REQUIRED | L11: NOT REQUIRED | M11: NOT REQUIRED | N11: NOT REQUIRED | O11: NOT REQUIRED | P11: NOT REQUIRED | Q11: NOT REQUIRED | R11: NOT REQUIRED | S11: 0 | U11: 0 | Y11: RECEIVED | Z11: NOT REQUIRED | AA11: NOT REQUIRED | AB11: NOT REQUIRED | AC11: 8404 N 75th St, Scottsdale, AZ 85258, USA
A12: 1708 | B12: ORDER COMPLETED | C12: ECHMEYER, KRISTINA & EVAN | D12: SERVICE-WARRANT | F12: 46204 | G12: 46204 | H12: NO | I12: NA | J12: NOT REQUIRED | K12: NOT REQUIRED | L12: NOT REQUIRED | M12: NOT REQUIRED | N12: NOT REQUIRED | O12: NOT REQUIRED | P12: NOT REQUIRED | Q12: NOT REQUIRED | R12: RECEIVED | S12: 0 | T12: 0 | U12: 0 | V12: 0 | W12: 0 | X12: 0 | Y12: NOT REQUIRED | Z12: NOT REQUIRED | AA12: NOT REQUIRED | AB12: NOT REQUIRED | AC12: 8321 Baseline Rd, Boulder, CO 80303, USA
A13: 1491 | B13: NEW | C13: KONA RE-DOING-GENCUSH | D13: COMMERCIAL | F13: 46204 | G13: 46204 | H13: NO | I13: NA | J13: NOT REQUIRED | K13: NOT REQUIRED | L13: NOT REQUIRED | M13: NOT STARTED | N13: NOT STARTED | O13: NOT STARTED | P13: NOT STARTED | Q13: NEED | R13: SAME NEED | S13: 20 | T13: 0 | U13: 0 | V13: 0 | W13: 0 | X13: 0 | Y13: NOT REQUIRED | Z13: NOT REQUIRED | AA13: NOT REQUIRED | AB13: NOT REQUIRED | AC13: 72-300 Maheawalu Drive, Kailua-Kona HI 96740
A14: 1662 | B14: ORDER COMPLETED | C14: KERYN GERBER | D14: SERVICE-WARRANT | E14: 46233 | F14: 46253 | G14: 46253 | H14: YES | I14: YES | J14: NOT REQUIRED | K14: COMPLETED | L14: NOT REQUIRED | M14: NOT REQUIRED | N14: NOT REQUIRED | O14: NOT REQUIRED | P14: NOT REQUIRED | Q14: NOT REQUIRED | R14: NOT REQUIRED | S14: 0 | T14: 1 | U14: 0 | V14: 0 | W14: 0.041666667 | X14: 0 | Y14: NOT REQUIRED | Z14: NOT REQUIRED | AA14: NOT REQUIRED | AB14: NOT REQUIRED | AC14: 4103 n 64th pl, Scottsdale, Arizona 85251
A15: 1663 | B15: ORDER COMPLETED | C15: DAVE MONTZ | D15: PICKUP | E15: 46212 | F15: 46204 | G15: 46204 | H15: NO | I15: YES | J15: NOT REQUIRED | K15: NOT REQUIRED | L15: NOT REQUIRED | M15: COMPLETED | N15: COMPLETED | O15: COMPLETED | P15: COMPLETED | Q15: RECEIVED | R15: SAME RECEIVED | S15: 1 | T15: 0 | U15: 0 | Y15: NOT REQUIRED | Z15: NOT REQUIRED | AA15: NOT REQUIRED | AB15: NOT REQUIRED | AC15: DROP & PICK AT FACTORY
A16: 1687 | B16: ORDER COMPLETED | C16: JEN BERGMAN | D16: SERVICE-WARRANT | F16: 46204 | G16: 46204 | H16: NO | I16: NA | J16: NOT REQUIRED | K16: NOT REQUIRED | L16: NOT REQUIRED | M16: COMPLETED | N16: COMPLETED | O16: COMPLETED | P16: COMPLETED | Q16: ON STOCK | R16: SAME RECEIVED | S16: 1 | T16: 0 | U16: 0 | Y16: NOT REQUIRED | Z16: NOT REQUIRED | AA16: NOT REQUIRED | AB16: NOT REQUIRED | AC16: 3386 S Stuart Ave, Gilbert, AZ 85297, USA
A17: 1702 | B17: ORDER COMPLETED | C17: JILL CUTRONE | D17: SERVICE-WARRANT | F17: 46204 | G17: 46204 | H17: NO | I17: NA | J17: NOT REQUIRED | K17: NOT REQUIRED | L17: COMPLETED | M17: NOT REQUIRED | N17: NOT REQUIRED | O17: NOT REQUIRED | P17: NOT REQUIRED | Q17: NOT REQUIRED | R17: NOT REQUIRED | Y17: NOT REQUIRED | Z17: NOT REQUIRED | AA17: NOT REQUIRED | AB17: NOT REQUIRED | AC17: 14762 N Strong Stone Dr, Oro Valley, AZ 85755, USA
A18: 1703 | B18: ORDER COMPLETED | C18: MIKE CHAFFEUR | D18: SERVICE-WARRANT | F18: 46204 | G18: 46204 | H18: NO | I18: NA | J18: NOT REQUIRED | K18: NOT REQUIRED | L18: NOT REQUIRED | M18: COMPLETED | N18: COMPLETED | O18: COMPLETED | P18: COMPLETED | Q18: NOT REQUIRED | R18: SAME RECEIVED | S18: 2 | Y18: NOT REQUIRED | Z18: NOT REQUIRED | AA18: NOT REQUIRED | AB18: NOT REQUIRED | AC18: 9431 N Solitude Canyon Fountain Hills AZ 85268
A19: 1696 | B19: ORDER COMPLETED | C19: LISA FORD | D19: SERVICE-WARRANT | F19: 46205 | G19: 46205 | H19: YES | I19: NA | J19: NOT REQUIRED | K19: NOT REQUIRED | L19: NOT REQUIRED | M19: COMPLETED | N19: COMPLETED | O19: COMPLETED | P19: COMPLETED | Q19: ON STOCK | R19: RECEIVED | S19: 1 | T19: 0 | U19: 0 | W19: 0 | X19: 0 | Y19: NOT REQUIRED | Z19: NOT REQUIRED | AA19: NOT REQUIRED | AB19: NOT REQUIRED | AC19: COLORADO
A20: 1704 | B20: ORDER COMPLETED | C20: LINDSAY MADERIA WALSH | D20: RESIDENTIAL | F20: 46205 | G20: 46205 | H20: YES | I20: NA | J20: NOT REQUIRED | K20: NOT REQUIRED | L20: NOT REQUIRED | M20: COMPLETED | N20: COMPLETED | O20: COMPLETED | P20: NOT REQUIRED | Q20: RECEIVED | R20: NOT REQUIRED | S20: 9 | T20: 0 | U20: 0 | W20: 0 | X20: 0 | Y20: NOT REQUIRED | Z20: NOT REQUIRED | AA20: NOT REQUIRED | AB20: NOT REQUIRED | AC20: 2055 Bear Hollow Dr, Park City, UT 84098, USA
A21: 1638 | B21: ORDER COMPLETED | C21: DIANE GALATI | D21: SERVICE | F21: 46209 | G21: 46210 | H21: YES | J21: NOT REQUIRED | K21: NOT REQUIRED | L21: IN PROGRESS | M21: NOT REQUIRED | N21: NOT REQUIRED | O21: NOT REQUIRED | P21: NOT REQUIRED | Q21: NOT REQUIRED | R21: NOT REQUIRED | S21: 0 | U21: 1 | Y21: NOT REQUIRED | Z21: NOT REQUIRED | AA21: NOT REQUIRED | AB21: NOT REQUIRED | AC21: 4939 E Horseshoe Rd, Paradise Valley, AZ 85253, USA
A22: 1605 | B22: ORDER COMPLETED | C22: DEANNE SPRENGER | D22: RESIDENTIAL | E22: 46212 | F22: 46210 | G22: 46210 | H22: YES | I22: YES | J22: NOT REQUIRED | K22: NOT REQUIRED | L22: NOT REQUIRED | M22: COMPLETED | N22: COMPLETED | O22: COMPLETED | P22: COMPLETED | Q22: NOT REQUIRED | R22: RECEIVED | S22: 1 | U22: 0 | Y22: NOT REQUIRED | Z22: NOT REQUIRED | AA22: NOT REQUIRED | AB22: NOT REQUIRED | AC22: 13452 E Desert Trail Scottsdale, AZ 85259
A23: 1643 | B23: ORDER COMPLETED | C23: MEGAN KELLY ADD-ON | D23: RESIDENTIAL | F23: 46210 | G23: 46211 | H23: YES | I23: NA | J23: COMPLETED | K23: COMPLETED | L23: COMPLETED | M23: COMPLETED | N23: COMPLETED | O23: COMPLETED | P23: COMPLETED | Q23: IN STOCK | R23: RECEIVED | S23: 5 | T23: 5 | U23: 0 | Y23: NOT REQUIRED | Z23: NOT REQUIRED | AA23: NOT REQUIRED | AB23: NOT REQUIRED | AC23: 10276 White Birch St, Presque Isle, MI 49777, USA
A24: 1521 | B24: ORDER COMPLETED | C24: RUSH SHOWROOM SWING CUSHION | D24: SHOWROOM SCOTTSDALE | F24: 46212 | G24: 46212 | H24: YES | I24: NA | J24: NOT REQUIRED | K24: NOT REQUIRED | L24: NOT REQUIRED | M24: COMPLETED | N24: COMPLETED | O24: COMPLETED | P24: COMPLETED | Q24: IN STOCK | R24: RECEIVED | S24: 1 | U24: 0 | Y24: NOT REQUIRED | Z24: NOT REQUIRED | AA24: NOT REQUIRED | AB24: NOT REQUIRED | AC24: 15037 N Scottsdale Rd Ste 120, Scottsdale, AZ 85254
A25: 1502 | B25: ORDER COMPLETED | C25: ROB ROY | D25: RESIDENTIAL | F25: 46217 | G25: 46218 | H25: YES | I25: NA | J25: COMPLETED | K25: COMPLETED | L25: COMPLETED | M25: COMPLETED | N25: COMPLETED | O25: COMPLETED | P25: COMPLETED | Q25: RECEIVED | R25: RECEIVED | S25: 18 | U25: 7 | Y25: NOT REQUIRED | Z25: NOT REQUIRED | AA25: NOT REQUIRED | AB25: NOT REQUIRED | AC25: CALIFORNIA
A26: 1573 | B26: ORDER COMPLETED | C26: SOLANA BEACH SHOWROOM 4-29 | D26: SHOWROOM | F26: 46217 | G26: 46218 | H26: YES | I26: NA | J26: COMPLETED | K26: COMPLETED | L26: NOT REQUIRED | M26: COMPLETED | N26: COMPLETED | O26: COMPLETED | P26: COMPLETED | Q26: RECEIVED | R26: RECEIVED | S26: 4 | U26: 0 | Y26: NOT REQUIRED | Z26: NOT REQUIRED | AA26: NOT REQUIRED | AB26: NOT REQUIRED | AC26: CALIFORNIA
A27: 1576 | B27: ORDER COMPLETED | C27: RICHARD AGUILAR | D27: RESIDENTIAL | F27: 46217 | G27: 46218 | H27: YES | I27: NA | J27: COMPLETED | K27: COMPLETED | L27: COMPLETED | M27: COMPLETED | N27: COMPLETED | O27: COMPLETED | P27: COMPLETED | Q27: RECEIVED | R27: RECEIVED | S27: 7 | U27: 3 | Y27: NOT REQUIRED | Z27: NOT REQUIRED | AA27: NOT REQUIRED | AB27: NOT REQUIRED | AC27: 5435 Calumet Ave, LA JOLLA, CA
A28: 1604 | B28: ORDER COMPLETED | C28: MELANIE SPAHN | D28: SERVICE | E28: 46218 | F28: 46217 | G28: 46218 | H28: YES | I28: YES | J28: NOT REQUIRED | K28: COMPLETED | L28: NOT REQUIRED | M28: NOT REQUIRED | N28: NOT REQUIRED | O28: NOT REQUIRED | P28: NOT REQUIRED | Q28: NOT REQUIRED | R28: NOT REQUIRED | S28: 0 | U28: 0 | Y28: NOT REQUIRED | Z28: NOT REQUIRED | AA28: NOT REQUIRED | AB28: NOT REQUIRED | AC28: 8621 E Clarendon Ave, Scottsdale, AZ 85251, USA
A29: 1610 | B29: ORDER COMPLETED | C29: PAUL DICOSMO-REDO | D29: REDOING | E29: 46211 | F29: 46217 | G29: 46217 | H29: YES | I29: YES | J29: NOT REQUIRED | K29: NOT REQUIRED | L29: COMPLETED | M29: COMPLETED | N29: COMPLETED | O29: COMPLETED | P29: COMPLETED | Q29: RECEIVED | R29: RECEIVED | S29: 2 | U29: 1 | Y29: RECEIVED | Z29: NOT REQUIRED | AA29: NOT REQUIRED | AB29: NOT REQUIRED | AC29: 18724 E Chandler Heights Rd, Queen Creek, AZ 85142, USA
A30: 1613 | B30: ORDER COMPLETED | C30: RAQUEL-JASON NORTON | D30: RESIDENTIAL | F30: 46217 | G30: 46218 | H30: YES | I30: NA | J30: COMPLETED | K30: COMPLETED | L30: NOT REQUIRED | M30: COMPLETED | N30: COMPLETED | O30: COMPLETED | P30: COMPLETED | Q30: RECEIVED | R30: RECEIVED | S30: 3 | T30: 3 | U30: 0 | Y30: NOT REQUIRED | Z30: NOT REQUIRED | AA30: NOT REQUIRED | AB30: NOT REQUIRED | AC30: CALIFORNIA
A31: 1614 | B31: ORDER COMPLETED | C31: BETH HOFFMAN | D31: RESIDENTIAL | F31: 46217 | G31: 46218 | H31: YES | I31: NA | J31: COMPLETED | K31: COMPLETED | L31: COMPLETED | M31: COMPLETED | N31: COMPLETED | O31: COMPLETED | P31: COMPLETED | Q31: RECEIVED | R31: RECEIVED | S31: 5 | U31: 4 | Y31: NOT REQUIRED | Z31: NOT REQUIRED | AA31: NOT REQUIRED | AB31: NOT REQUIRED | AC31: CALIFORNIA
A32: 1624 | B32: ORDER COMPLETED | C32: RAQUEL-JASON NORTON | D32: RESIDENTIAL | F32: 46217 | G32: 46218 | H32: YES | I32: NA | J32: COMPLETED | K32: COMPLETED | L32: COMPLETED | M32: NOT REQUIRED | N32: NOT REQUIRED | O32: NOT REQUIRED | P32: NOT REQUIRED | Q32: NOT REQUIRED | R32: NOT REQUIRED | S32: 0 | T32: 1 | U32: 0 | Y32: NOT REQUIRED | Z32: NOT REQUIRED | AA32: NOT REQUIRED | AB32: NOT REQUIRED | AC32: 1468 Rimcrest Ct, BONITA CA 91902
A33: 1651 | B33: ORDER COMPLETED | C33: CHAD | D33: SERVICE | E33: 46212 | F33: 46217 | G33: 46218 | H33: YES | I33: YES | J33: NOT REQUIRED | K33: COMPLETED | L33: COMPLETED | M33: NOT REQUIRED | N33: NOT REQUIRED | O33: NOT REQUIRED | P33: NOT REQUIRED | Q33: NOT REQUIRED | R33: NOT REQUIRED | Y33: NOT REQUIRED | Z33: NOT REQUIRED | AA33: NOT REQUIRED | AB33: NOT REQUIRED | AC33: 13260 N 83rd Pl SCOTTSDALE AZ 85260
A34: 1653 | B34: ORDER COMPLETED | C34: CA AMAR TAKHUR | D34: RESIDENTIAL | F34: 46217 | G34: 46219 | H34: YES | I34: NA | J34: NOT REQUIRED | K34: NOT REQUIRED | L34: COMPLETED | M34: NOT REQUIRED | N34: NOT REQUIRED | O34: NOT REQUIRED | P34: NOT REQUIRED | Q34: NOT REQUIRED | R34: NOT REQUIRED | S34: 0 | T34: 0 | U34: 1 | Y34: NOT REQUIRED | Z34: NOT REQUIRED | AA34: NOT REQUIRED | AB34: NOT REQUIRED | AC34: 304 N Sierra Ave, Solana Beach, CA 92075
A35: 1608 | B35: ORDER COMPLETED | C35: ANDREA SYDENHAM-SERVICE | D35: SERVICE | E35: 46202 | F35: 46218 | G35: 46219 | H35: YES | I35: YES | J35: NOT REQUIRED | K35: COMPLETED | L35: NOT REQUIRED | M35: NOT REQUIRED | N35: NOT REQUIRED | O35: NOT REQUIRED | P35: NOT REQUIRED | Q35: NOT REQUIRED | R35: NOT REQUIRED | S35: 0 | U35: 0 | Y35: NOT REQUIRED | Z35: NOT REQUIRED | AA35: NOT REQUIRED | AB35: NOT REQUIRED | AC35: 26814 Boulder Ln, Scottsdale, AZ 85255, USA
A36: 1617 | B36: ORDER COMPLETED | C36: REDO SHELLY GROTHAUS | D36: WARRANTY | E36: 46202 | F36: 46218 | G36: 46219 | H36: YES | I36: YES | J36: NOT REQUIRED | K36: NOT REQUIRED | L36: NOT REQUIRED | M36: COMPLETED | N36: COMPLETED | O36: COMPLETED | P36: COMPLETED | Q36: IN STOCK | R36: SAME-READY | S36: 2 | U36: 0 | Y36: NOT REQUIRED | Z36: NOT REQUIRED | AA36: NOT REQUIRED | AB36: NOT REQUIRED | AC36: 10801 E Happy Valley Rd, Scottsdale, AZ 85255, USA
A37: 1654 | B37: ORDER COMPLETED | C37: CA Edisoon Reynoso | D37: SERVICE | F37: 46218 | G37: 46219 | H37: YES | I37: NA | J37: NOT REQUIRED | K37: NOT REQUIRED | L37: NOT REQUIRED | M37: NOT REQUIRED | N37: NOT REQUIRED | O37: NOT REQUIRED | P37: NOT REQUIRED | Q37: NOT REQUIRED | R37: NOT REQUIRED | S37: 0 | T37: 0 | U37: 0 | Y37: NOT REQUIRED | Z37: NOT REQUIRED | AA37: NOT REQUIRED | AB37: NOT REQUIRED | AC37: 5986 Greensview Ct, RANCHO SANTA FE, CA 92067
A38: 1607 | B38: ORDER COMPLETED | C38: STEPHANIE EVERS-SERVICE | D38: SERVICE | E38: 46204 | F38: 46219 | G38: 46219 | H38: YES | I38: YES | J38: NOT REQUIRED | K38: COMPLETED | L38: NOT REQUIRED | M38: NOT REQUIRED | N38: NOT REQUIRED | O38: NOT REQUIRED | P38: NOT REQUIRED | Q38: NOT REQUIRED | R38: NOT REQUIRED | S38: 0 | U38: 0 | Y38: NOT REQUIRED | Z38: NOT REQUIRED | AA38: NOT REQUIRED | AB38: NOT REQUIRED | AC38: 5736 E Lowden Rd, Cave Creek, AZ 85331, USA
A39: 1669 | B39: ORDER COMPLETED | C39: HAMID SHOWROOM 7-17-26 | D39: COMMERCIAL | F39: 46219 | G39: 46219 | H39: YES | I39: NA | J39: COMPLETED | K39: COMPLETED | L39: COMPLETED | M39: COMPLETED | N39: COMPLETED | O39: COMPLETED | P39: COMPLETED | Q39: IN STOCK | R39: RECEIVED | S39: 8 | Y39: NOT REQUIRED | Z39: NOT REQUIRED | AA39: NOT REQUIRED | AB39: NOT REQUIRED | AC39: SCOTTSDALE SHOWROOM
A40: 1546 | B40: ORDER COMPLETED | C40: JIM-CAROL LAUB | D40: RESIDENTIAL | F40: 46223 | G40: 46225 | H40: YES | I40: NA | J40: COMPLETED | K40: COMPLETED | L40: COMPLETED | M40: COMPLETED | N40: COMPLETED | O40: COMPLETED | P40: COMPLETED | Q40: RECEIVED | R40: RECEIVED | S40: 19 | U40: 10 | Y40: NOT REQUIRED | Z40: RECEIVED | AA40: NOT REQUIRED | AB40: RECEIVED | AC40: 8745 North Lookout Lane, Park City, UT
...

Sheet Export Lines
B1: Order # | C1: Customer info | D1: Order Type | E1: PRODUCT. DEAD LINE | F1: PU/ DROP | G1: Delivery Date | H1: Cushions | I1: 3RD PARTY | J1: Covers | K1: Umbre- | L1: Tenjam | M1: Firepit System | N1: Metal | O1: Powder Coat | P1: Dekton | Q1: Delivery Address | R1: Order Status | S1: Start Date | T1: End Date | U1: Order payment status
B2: 184 | C2: LAMB, CINDY & JOHN | H2: Not started | N2: Not Started | O2: Not Started | P2: Not started | Q2: complete | S2: 44595 | T2: 44926 | U2: Not collected
B3: 186 | C3: CAROLL, DAVID | H3: Sew Start | N3: Not Started | O3: Not Started | P3: Not started | Q3: complete | S3: 44600 | T3: 44788 | U3: Not collected
B4: 199 | C4: PALMER, TERESA | G4: 44785 | H4: Completed | N4: Completed | O4: Completed | P4: Completed | Q4: complete | S4: 44621 | T4: 44666 | U4: Collected
B5: 248 | C5: TRADER, PAULA & BOB | H5: Sew End | N5: Not Started | O5: Not Started | P5: Not started | Q5: complete | S5: 44686 | T5: 44805 | U5: Not collected
B6: 259 | C6: BLOEBAUM, AMY | G6: 44798 | H6: Sew End | N6: Completed | O6: Not Started | P6: Completed | Q6: complete | S6: 44697 | T6: 44795 | U6: Collected
B7: 262 | C7: SALZMAN, JENNIFER | H7: Not required | N7: Not Started | O7: Not Started | P7: Not started | Q7: complete | S7: 44704 | T7: 44775 | U7: Ready to collect
B8: 263 | C8: BARAVADA, ATLAS | H8: Completed | N8: Completed | O8: Completed | P8: Not Required | Q8: complete | S8: 44705 | T8: 44926 | U8: Not collected
B9: 267 | C9: JONES, MARY LU | G9: 44788 | H9: Sew End | N9: Grind Start | O9: Not Started | P9: Not started | Q9: complete | S9: 44712 | T9: 44757 | U9: Collected
B10: 269 | C10: BICKELHAUPT, REESE | G10: 44784 | H10: Sew End | N10: Completed | O10: Powder Coat Start | P10: Cut Start | Q10: complete | S10: 44712 | T10: 44770 | U10: Collected
B11: 274 | C11: GUELI, SUSAN | G11: 44792 | H11: Sew Start | N11: Cut Start | O11: Not Started | P11: Not started | Q11: complete | S11: 44720 | T11: 44776 | U11: Collected
B12: 276 | C12: BELL, SUSAN | G12: 44783 | H12: Completed | N12: Completed | O12: Completed | P12: Polish Start | Q12: complete | S12: 44720 | T12: 44754 | U12: Collected
B13: 279 | C13: MAPSTEAD, JILL & JIM | G13: 44784 | H13: Completed | N13: Not Started | O13: Not Started | P13: Cut End | Q13: complete | S13: 44722 | T13: 44775 | U13: Collected
B14: 280 | C14: forsberg, clay | H14: Sew End | N14: Cut End | O14: Not Started | P14: Not Required | Q14: complete | S14: 44730 | T14: 44837 | U14: Collected
B15: 282 | C15: Sullivan, Mike | H15: Sew End | N15: Not Started | O15: Not Started | P15: Not started | Q15: complete | S15: 44734 | T15: 44785 | U15: Not collected
B16: 284 | C16: Peggy, Garret | G16: 44782 | H16: Sew End | N16: Completed | O16: Completed | P16: Completed | Q16: complete | S16: 44734 | T16: 44764 | U16: Collected
B17: 285 | C17: Tesar, Jim | H17: Not started | N17: Not Started | O17: Not Started | P17: Not started | Q17: complete | S17: 44734 | T17: 44816 | U17: Not collected
B18: 287 | C18: GARCIA, JON | H18: Sew End | N18: Not Started | O18: Not Started | P18: Not started | Q18: complete | S18: 44737 | T18: 44844 | U18: Not collected
B19: 288 | C19: SIVARA, LISSA | G19: 44795 | H19: Completed | N19: Weld Start | O19: Not Started | P19: Not started | Q19: complete | S19: 44737 | T19: 44764 | U19: Collected
B20: 289 | C20: WELLS, AMANDA & MATT | H20: Issue | N20: Not Started | O20: Not Started | P20: Not started | Q20: complete | S20: 44737 | T20: 44790 | U20: Not collected
B21: 290 | C21: KROLL, BRIAN | H21: Cut End | N21: Not Started | O21: Not Started | P21: Not started | Q21: complete | S21: 44740 | T21: 44803 | U21: Not collected
B22: 291 | C22: JOFFE, BETH & AARON | G22: 44791 | H22: Completed | N22: Not Started | O22: Not Started | P22: Cut End | Q22: complete | S22: 44740 | T22: 44771 | U22: Collected
B23: 292 | C23: KILIAN, STEVE & DEBBIE | H23: Completed | N23: Completed | O23: Not Started | P23: Completed | Q23: complete | S23: 44740 | T23: 44848 | U23: Ready to collect
B24: 293 | C24: PATEL, RANJAN | H24: Sew Start | N24: Not Started | O24: Not Started | P24: Not started | Q24: complete | S24: 44740 | T24: 44790 | U24: Not collected
B25: 294 | C25: VOTTIERO, PHIL & SHERRIE | H25: Cut End | N25: Not Started | O25: Not Started | P25: Not started | Q25: complete | S25: 44740 | T25: 44793 | U25: Not collected
B26: 296 | C26: FRIESEN, DON | H26: Not started | N26: Not Started | O26: Not Started | P26: Not started | Q26: complete | S26: 44748 | T26: 44817 | U26: Not collected
B27: 297 | C27: Bochner, Cheryl | H27: Sew Start | N27: Not Started | O27: Not Started | P27: Not started | Q27: complete | S27: 44749 | T27: 44792 | U27: Not collected
B28: 298 | C28: ECHMEYER, KRISTINA & EVAN | H28: Not started | N28: Not Started | O28: Not Started | P28: Not started | Q28: complete | S28: 44749 | T28: 44793 | U28: Not collected
B29: 299 | C29: Lester, Kay | H29: Cut Start | N29: Not Started | O29: Not Started | P29: Not started | Q29: complete | S29: 44750 | T29: 44785 | U29: Not collected
B30: 300 | C30: COOPER, GREG | H30: Issue | N30: Not Started | O30: Not Started | P30: Not started | Q30: complete | S30: 44755 | T30: 44824 | U30: Not collected
B31: 301 | C31: EICHLER, WENDI & JOHN | H31: Issue | N31: Not Started | O31: Not Started | P31: Not started | Q31: complete | S31: 44755 | T31: 44825 | U31: Not collected
B32: 302 | C32: MCGELLA, SUSAN | H32: Issue | N32: Not Started | O32: Not Started | P32: Not started | Q32: complete | S32: 44756 | T32: 44848 | U32: Not collected
B33: 303 | C33: WALLACH, MICHELLE | H33: Not started | N33: Not Started | O33: Not Started | P33: Not started | Q33: complete | S33: 44760 | T33: 44790 | U33: Not collected
B34: 304 | C34: ROBERTS, CINDY | H34: Not started | N34: Not Started | O34: Not Started | P34: Not started | Q34: complete | S34: 44762 | T34: 44804 | U34: Not collected
... B36: 306 | C36: CLARK, ELIZABETH | H36: Not started | N36: Not Started | O36: Not Started | P36: Not started | Q36: complete | S36: 44764 | T36: 44816 | U36: Not collected
B37: 307 | C37: SUSAN & RICHARD, GROSSMAN | G37: 44791 | H37: Not required | N37: Completed | O37: Sandblast End | P37: Not started | Q37: complete | S37: 44765 | T37: 44772 | U37: Collected
B38: 308 | C38: ONE CAMELBACK, ONE CAMELBACK | H38: Not started | N38: Not Started | O38: Not Started | P38: Not started | Q38: complete | S38: 44767 | T38: 44826 | U38: Not collected
B39: 309 | C39: WILVER, PETE & MICHELLE | H39: Not started | N39: Not Started | O39: Not Started | P39: Not started | Q39: complete | S39: 44768 | T39: 44830 | U39: Not collected
B40: 310 | C40: SIMPSON, AMBER | H40: Not started | N40: Not Started | O40: Not Started | P40: Not started | Q40: complete | S40: 44768 | T40: 44831 | U40: Not collected
B41: 311 | C41: Uzcategui, Nicolas | H41: Issue | N41: Not Started | O41: Not Started | P41: Not Required | Q41: complete | S41: 44770 | T41: 44791 | U41: Not collected
...

Sheet Copy of CAPACITY
A1: CC PATIO — CAPACITY & LEAD-TIME PLANNER
A2: Live from the NEW tab · each department independent · schedule real weekly hours in the planner and every date re-solves
A4: SETTINGS
A5: Capacity (hrs / wk / dept, default) | B5: 49 | C5: ← default; override per week in planner
A6: Lead buffer (days before delivery) | B6: 1
A7: Today | B7: =TODAY() -> 46255
A8: Cushion drops off once CORTE + SEW are COMPLETED (filling is not a constraint). Metal drops at POWDER COAT = COMPLETED. Dekton drops at DEKTON = COMPLETED.
A10: SNAPSHOT
A11: ORDERS BEHIND | C11: CATCH-UP CUSH (h) | E11: CATCH-UP PC (h) | G11: THIS-WK LOAD (h) | I11: NEXT-WK LOAD (h) | K11: BINDING DEPT
A12: =COUNTIF(M39:M88,"BEHIND") -> 50 | C12: =B29 -> 0 | E12: =B30 -> 0 | G12: =B29+B30+B31 -> 0 | I12: =C29+C30+C31 -> 0 | K12: {=IF(MAX(J16:J18)<=0,"all OK",INDEX(G16:G18,MATCH(MAX(J16:J18),J16:J18,0)))} -> all OK
A14: DEPARTMENT LOAD | G14: REQUIRED RUN-RATE vs CAPACITY
A15: DEPARTMENT | B15: REMAIN h | C15: WEEKS @def | D15: CLEAR DATE | E15: DROPS WHEN | G15: DEPARTMENT | H15: REQ h/wk | I15: CAPACITY | J15: GAP | K15: VERDICT
A16: Cushion | B16: =(SUMIFS(NEW!$V$2:$V$1528,NEW!$B$2:$B$1528,"NEW",NEW!$M$2:$M$1528,"<>COMPLETED")-SUMIFS(NEW!$V$2:$V$1528,NEW!$B$2:$B$1528,"NEW",NEW!$M$2:$M$1528,"<>COMPLETED",NEW!$N$2:$N$1528,"COMPLETED",NEW!$O$2:$O$1528,"COMPLETED"))*24 -> 380.03333 | C16: =B16/$B$5 -> 7.7557823 | D16: =$B$7+C16*7 -> 46309.29 | E16: CORTE + SEW = COMPLETED | G16: Cushion | H16: =MAX(P39:P88) -> 0 | I16: =$B$5 -> 49 | J16: =H16-I16 -> -49 | K16: =IF(J16<=0,"OK — fits","SHORT "&TEXT(J16,"0")&" h/wk") -> OK — fits
A17: Powder Coat (Metal) | B17: =SUMIFS(NEW!$W$2:$W$1528,NEW!$B$2:$B$1528,"NEW",NEW!$K$2:$K$1528,"<>COMPLETED")*24 -> 300.33333 | C17: =B17/$B$5 -> 6.1292517 | D17: =$B$7+C17*7 -> 46297.905 | E17: POWDER COAT = COMPLETED | G17: Powder Coat (Metal) | H17: =MAX(Q39:Q88) -> 0 | I17: =$B$5 -> 49 | J17: =H17-I17 -> -49 | K17: =IF(J17<=0,"OK — fits","SHORT "&TEXT(J17,"0")&" h/wk") -> OK — fits
A18: Dekton | B18: =SUMIFS(NEW!$X$2:$X$1528,NEW!$B$2:$B$1528,"NEW",NEW!$L$2:$L$1528,"<>COMPLETED")*24 -> 181 | C18: =B18/$B$5 -> 3.6938776 | D18: =$B$7+C18*7 -> 46280.857 | E18: DEKTON = COMPLETED | G18: Dekton | H18: =MAX(R39:R88) -> 0 | I18: =$B$5 -> 49 | J18: =H18-I18 -> -49 | K18: =IF(J18<=0,"OK — fits","SHORT "&TEXT(J18,"0")&" h/wk") -> OK — fits
G19: REQ = rate to finish every dated order by (delivery − buffer), set by the tightest cumulative stretch. Orders due within the buffer are catch-up (see snapshot).
A21: WEEKLY CAPACITY PLANNER — type the hours you'll actually staff each week (yellow = edit)
A22: Department | B22: =$B$7+0 -> 46255 | C22: =$B$7+7 -> 46262 | D22: =$B$7+14 -> 46269 | E22: =$B$7+21 -> 46276 | F22: =$B$7+28 -> 46283 | G22: =$B$7+35 -> 46290 | H22: =$B$7+42 -> 46297 | I22: =$B$7+49 -> 46304
A23: Cushion | B23: 50 | C23: 50 | D23: 36 | E23: 36 | F23: 36 | G23: 36 | H23: 36 | I23: 36
A24: Powder Coat | B24: 36 | C24: 36 | D24: 36 | E24: 36 | F24: 36 | G24: 36 | H24: 36 | I24: 36
A25: Dekton | B25: 36 | C25: 0 | D25: 36 | E25: 36 | F25: 36 | G25: 36 | H25: 36 | I25: 36
A26: Example loaded: Cushion 50 h this & next week (overtime), Dekton 0 next week (people moved out). Edit any yellow cell — the timeline and clear-dates update.
A27: LOAD vs CAPACITY TIMELINE — work landing each week (by target) vs capacity scheduled above
A28: Week of → | B28: =B22 -> 46255 | C28: =C22 -> 46262 | D28: =D22 -> 46269 | E28: =E22 -> 46276 | F28: =F22 -> 46283 | G28: =G22 -> 46290 | H28: =H22 -> 46297 | I28: =I22 -> 46304
A29: Cushion demand | B29: =SUMIFS($E$39:$E$88,$D$39:$D$88,"<"&(B$28+7)) -> 0 | C29: =SUMIFS($E$39:$E$88,$D$39:$D$88,">="&C$28,$D$39:$D$88,"<"&(C$28+7)) -> 0 | D29: =SUMIFS($E$39:$E$88,$D$39:$D$88,">="&D$28,$D$39:$D$88,"<"&(D$28+7)) -> 0 | E29: =SUMIFS($E$39:$E$88,$D$39:$D$88,">="&E$28,$D$39:$D$88,"<"&(E$28+7)) -> 0 | F29: =SUMIFS($E$39:$E$88,$D$39:$D$88,">="&F$28,$D$39:$D$88,"<"&(F$28+7)) -> 0 | G29: =SUMIFS($E$39:$E$88,$D$39:$D$88,">="&G$28,$D$39:$D$88,"<"&(G$28+7)) -> 0 | H29: =SUMIFS($E$39:$E$88,$D$39:$D$88,">="&H$28,$D$39:$D$88,"<"&(H$28+7)) -> 0 | I29: =SUMIFS($E$39:$E$88,$D$39:$D$88,">="&I$28,$D$39:$D$88,"<"&(I$28+7)) -> 0
A30: Powder Coat demand | B30: =SUMIFS($F$39:$F$88,$D$39:$D$88,"<"&(B$28+7)) -> 0 | C30: =SUMIFS($F$39:$F$88,$D$39:$D$88,">="&C$28,$D$39:$D$88,"<"&(C$28+7)) -> 0 | D30: =SUMIFS($F$39:$F$88,$D$39:$D$88,">="&D$28,$D$39:$D$88,"<"&(D$28+7)) -> 0 | E30: =SUMIFS($F$39:$F$88,$D$39:$D$88,">="&E$28,$D$39:$D$88,"<"&(E$28+7)) -> 0 | F30: =SUMIFS($F$39:$F$88,$D$39:$D$88,">="&F$28,$D$39:$D$88,"<"&(F$28+7)) -> 0 | G30: =SUMIFS($F$39:$F$88,$D$39:$D$88,">="&G$28,$D$39:$D$88,"<"&(G$28+7)) -> 0 | H30: =SUMIFS($F$39:$F$88,$D$39:$D$88,">="&H$28,$D$39:$D$88,"<"&(H$28+7)) -> 0 | I30: =SUMIFS($F$39:$F$88,$D$39:$D$88,">="&I$28,$D$39:$D$88,"<"&(I$28+7)) -> 0
A31: Dekton demand | B31: =SUMIFS($G$39:$G$88,$D$39:$D$88,"<"&(B$28+7)) -> 0 | C31: =SUMIFS($G$39:$G$88,$D$39:$D$88,">="&C$28,$D$39:$D$88,"<"&(C$28+7)) -> 0 | D31: =SUMIFS($G$39:$G$88,$D$39:$D$88,">="&D$28,$D$39:$D$88,"<"&(D$28+7)) -> 0 | E31: =SUMIFS($G$39:$G$88,$D$39:$D$88,">="&E$28,$D$39:$D$88,"<"&(E$28+7)) -> 0 | F31: =SUMIFS($G$39:$G$88,$D$39:$D$88,">="&F$28,$D$39:$D$88,"<"&(F$28+7)) -> 0 | G31: =SUMIFS($G$39:$G$88,$D$39:$D$88,">="&G$28,$D$39:$D$88,"<"&(G$28+7)) -> 0 | H31: =SUMIFS($G$39:$G$88,$D$39:$D$88,">="&H$28,$D$39:$D$88,"<"&(H$28+7)) -> 0 | I31: =SUMIFS($G$39:$G$88,$D$39:$D$88,">="&I$28,$D$39:$D$88,"<"&(I$28+7)) -> 0
A32: Cushion — behind by (h) | B32: =MAX(0,SUM($B$29:B$29)-SUM($B$23:B$23)) -> 0 | C32: =MAX(0,SUM($B$29:C$29)-SUM($B$23:C$23)) -> 0 | D32: =MAX(0,SUM($B$29:D$29)-SUM($B$23:D$23)) -> 0 | E32: =MAX(0,SUM($B$29:E$29)-SUM($B$23:E$23)) -> 0 | F32: =MAX(0,SUM($B$29:F$29)-SUM($B$23:F$23)) -> 0 | G32: =MAX(0,SUM($B$29:G$29)-SUM($B$23:G$23)) -> 0 | H32: =MAX(0,SUM($B$29:H$29)-SUM($B$23:H$23)) -> 0 | I32: =MAX(0,SUM($B$29:I$29)-SUM($B$23:I$23)) -> 0
A33: Powder Coat — behind by (h) | B33: =MAX(0,SUM($B$30:B$30)-SUM($B$24:B$24)) -> 0 | C33: =MAX(0,SUM($B$30:C$30)-SUM($B$24:C$24)) -> 0 | D33: =MAX(0,SUM($B$30:D$30)-SUM($B$24:D$24)) -> 0 | E33: =MAX(0,SUM($B$30:E$30)-SUM($B$24:E$24)) -> 0 | F33: =MAX(0,SUM($B$30:F$30)-SUM($B$24:F$24)) -> 0 | G33: =MAX(0,SUM($B$30:G$30)-SUM($B$24:G$24)) -> 0 | H33: =MAX(0,SUM($B$30:H$30)-SUM($B$24:H$24)) -> 0 | I33: =MAX(0,SUM($B$30:I$30)-SUM($B$24:I$24)) -> 0
A34: Dekton — behind by (h) | B34: =MAX(0,SUM($B$31:B$31)-SUM($B$25:B$25)) -> 0 | C34: =MAX(0,SUM($B$31:C$31)-SUM($B$25:C$25)) -> 0 | D34: =MAX(0,SUM($B$31:D$31)-SUM($B$25:D$25)) -> 0 | E34: =MAX(0,SUM($B$31:E$31)-SUM($B$25:E$25)) -> 0 | F34: =MAX(0,SUM($B$31:F$31)-SUM($B$25:F$25)) -> 0 | G34: =MAX(0,SUM($B$31:G$31)-SUM($B$25:G$25)) -> 0 | H34: =MAX(0,SUM($B$31:H$31)-SUM($B$25:H$25)) -> 0 | I34: =MAX(0,SUM($B$31:I$31)-SUM($B$25:I$25)) -> 0
A35: 'Behind by' = cumulative demand minus cumulative scheduled capacity through that week. 0 (green) = keeping up; >0 (red) = that many hours late entering the next week.
A36: ORDER WORKLIST — sorted by target; work top-down (hours drop as depts are marked COMPLETED)
A38: ORDER # | B38: CUSTOMER | C38: DELIVERY | D38: TARGET | E38: CUSH h | F38: PC h | G38: DEKT h | H38: Σ CUSH | I38: Σ PC | J38: Σ DEKT | K38: PROJ DONE | L38: DAYS vs TGT | M38: STATUS | N38: HEALTH | P38: req·c | Q38: req·pc | R38: req·dk
A39: =NEW!A1235 -> 1376 | B39: =NEW!C1235 -> ROXANN FREDERICK | C39: =NEW!G1235 -> 45986 | D39: =IF(ISNUMBER(C39),C39-$B$6,"") -> 45985 | E39: =IF(OR(NEW!M1235="COMPLETED",AND(NEW!N1235="COMPLETED",NEW!O1235="COMPLETED")),0,NEW!V1235*24) -> 0 | F39: =IF(NEW!K1235="COMPLETED",0,NEW!W1235*24) -> 0 | G39: =IF(NEW!L1235="COMPLETED",0,NEW!X1235*24) -> 0 | H39: =SUM(E$39:E39) -> 0 | I39: =SUM(F$39:F39) -> 0 | J39: =SUM(G$39:G39) -> 0 | K39: =$B$7+MAX(H39,I39,J39)/$B$5*7 -> 46255 | L39: =IF(ISNUMBER(D39),D39-K39,"") -> -270 | M39: =IF(ISNUMBER(D39),IF(L39<0,"BEHIND",IF(L39<$B$6,"START NOW","ON TRACK")),"no date") -> BEHIND | N39: =IF(ISNUMBER(D39),IF(L39<0,"● LATE",IF(L39<7,"● TIGHT","● OK")),"") -> ● LATE | P39: =IF(ISNUMBER(D39),IF((D39-$B$7)>=7,H39/((D39-$B$7)/7),""),"") | Q39: =IF(ISNUMBER(D39),IF((D39-$B$7)>=7,I39/((D39-$B$7)/7),""),"") | R39: =IF(ISNUMBER(D39),IF((D39-$B$7)>=7,J39/((D39-$B$7)/7),""),"")
A40: =NEW!A1382 -> 1522 | B40: =NEW!C1382 -> JOAN RASKIN-BROKEN FIRE PIT | C40: =NEW!G1382 -> 46100 | D40: =IF(ISNUMBER(C40),C40-$B$6,"") -> 46099 | E40: =IF(OR(NEW!M1382="COMPLETED",AND(NEW!N1382="COMPLETED",NEW!O1382="COMPLETED")),0,NEW!V1382*24) -> 0 | F40: =IF(NEW!K1382="COMPLETED",0,NEW!W1382*24) -> 0 | G40: =IF(NEW!L1382="COMPLETED",0,NEW!X1382*24) -> 0 | H40: =SUM(E$39:E40) -> 0 | I40: =SUM(F$39:F40) -> 0 | J40: =SUM(G$39:G40) -> 0 | K40: =$B$7+MAX(H40,I40,J40)/$B$5*7 -> 46255 | L40: =IF(ISNUMBER(D40),D40-K40,"") -> -156 | M40: =IF(ISNUMBER(D40),IF(L40<0,"BEHIND",IF(L40<$B$6,"START NOW","ON TRACK")),"no date") -> BEHIND | N40: =IF(ISNUMBER(D40),IF(L40<0,"● LATE",IF(L40<7,"● TIGHT","● OK")),"") -> ● LATE | P40: =IF(ISNUMBER(D40),IF((D40-$B$7)>=7,H40/((D40-$B$7)/7),""),"") | Q40: =IF(ISNUMBER(D40),IF((D40-$B$7)>=7,I40/((D40-$B$7)/7),""),"") | R40: =IF(ISNUMBER(D40),IF((D40-$B$7)>=7,J40/((D40-$B$7)/7),""),"")
A41: =NEW!A1388 -> 1529 | B41: =NEW!C1388 -> GINA PIPER | C41: =NEW!G1388 -> 46143 | D41: =IF(ISNUMBER(C41),C41-$B$6,"") -> 46142 | E41: =IF(OR(NEW!M1388="COMPLETED",AND(NEW!N1388="COMPLETED",NEW!O1388="COMPLETED")),0,NEW!V1388*24) -> 0 | F41: =IF(NEW!K1388="COMPLETED",0,NEW!W1388*24) -> 0 | G41: =IF(NEW!L1388="COMPLETED",0,NEW!X1388*24) -> 0 | H41: =SUM(E$39:E41) -> 0 | I41: =SUM(F$39:F41) -> 0 | J41: =SUM(G$39:G41) -> 0 | K41: =$B$7+MAX(H41,I41,J41)/$B$5*7 -> 46255 | L41: =IF(ISNUMBER(D41),D41-K41,"") -> -113 | M41: =IF(ISNUMBER(D41),IF(L41<0,"BEHIND",IF(L41<$B$6,"START NOW","ON TRACK")),"no date") -> BEHIND | N41: =IF(ISNUMBER(D41),IF(L41<0,"● LATE",IF(L41<7,"● TIGHT","● OK")),"") -> ● LATE | P41: =IF(ISNUMBER(D41),IF((D41-$B$7)>=7,H41/((D41-$B$7)/7),""),"") | Q41: =IF(ISNUMBER(D41),IF((D41-$B$7)>=7,I41/((D41-$B$7)/7),""),"") | R41: =IF(ISNUMBER(D41),IF((D41-$B$7)>=7,J41/((D41-$B$7)/7),""),"")
A42: =NEW!A1393 -> 1534 | B42: =NEW!C1393 -> RITA-RICHARD RUSSEL | C42: =NEW!G1393 -> 46154 | D42: =IF(ISNUMBER(C42),C42-$B$6,"") -> 46153 | E42: =IF(OR(NEW!M1393="COMPLETED",AND(NEW!N1393="COMPLETED",NEW!O1393="COMPLETED")),0,NEW!V1393*24) -> 0 | F42: =IF(NEW!K1393="COMPLETED",0,NEW!W1393*24) -> 0 | G42: =IF(NEW!L1393="COMPLETED",0,NEW!X1393*24) -> 0 | H42: =SUM(E$39:E42) -> 0 | I42: =SUM(F$39:F42) -> 0 | J42: =SUM(G$39:G42) -> 0 | K42: =$B$7+MAX(H42,I42,J42)/$B$5*7 -> 46255 | L42: =IF(ISNUMBER(D42),D42-K42,"") -> -102 | M42: =IF(ISNUMBER(D42),IF(L42<0,"BEHIND",IF(L42<$B$6,"START NOW","ON TRACK")),"no date") -> BEHIND | N42: =IF(ISNUMBER(D42),IF(L42<0,"● LATE",IF(L42<7,"● TIGHT","● OK")),"") -> ● LATE | P42: =IF(ISNUMBER(D42),IF((D42-$B$7)>=7,H42/((D42-$B$7)/7),""),"") | Q42: =IF(ISNUMBER(D42),IF((D42-$B$7)>=7,I42/((D42-$B$7)/7),""),"") | R42: =IF(ISNUMBER(D42),IF((D42-$B$7)>=7,J42/((D42-$B$7)/7),""),"")
A43: =NEW!A1394 -> 1535 | B43: =NEW!C1394 -> BAHAMAS-CHRIS PRICE | C43: =NEW!G1394 -> 46181 | D43: =IF(ISNUMBER(C43),C43-$B$6,"") -> 46180 | E43: =IF(OR(NEW!M1394="COMPLETED",AND(NEW!N1394="COMPLETED",NEW!O1394="COMPLETED")),0,NEW!V1394*24) -> 0 | F43: =IF(NEW!K1394="COMPLETED",0,NEW!W1394*24) -> 0 | G43: =IF(NEW!L1394="COMPLETED",0,NEW!X1394*24) -> 0 | H43: =SUM(E$39:E43) -> 0 | I43: =SUM(F$39:F43) -> 0 | J43: =SUM(G$39:G43) -> 0 | K43: =$B$7+MAX(H43,I43,J43)/$B$5*7 -> 46255 | L43: =IF(ISNUMBER(D43),D43-K43,"") -> -75 | M43: =IF(ISNUMBER(D43),IF(L43<0,"BEHIND",IF(L43<$B$6,"START NOW","ON TRACK")),"no date") -> BEHIND | N43: =IF(ISNUMBER(D43),IF(L43<0,"● LATE",IF(L43<7,"● TIGHT","● OK")),"") -> ● LATE | P43: =IF(ISNUMBER(D43),IF((D43-$B$7)>=7,H43/((D43-$B$7)/7),""),"") | Q43: =IF(ISNUMBER(D43),IF((D43-$B$7)>=7,I43/((D43-$B$7)/7),""),"") | R43: =IF(ISNUMBER(D43),IF((D43-$B$7)>=7,J43/((D43-$B$7)/7),""),"")
A44: =NEW!A1395 -> 1536 | B44: =NEW!C1395 -> BRUCE SUSAN HALL | C44: =NEW!G1395 -> 46149 | D44: =IF(ISNUMBER(C44),C44-$B$6,"") -> 46148 | E44: =IF(OR(NEW!M1395="COMPLETED",AND(NEW!N1395="COMPLETED",NEW!O1395="COMPLETED")),0,NEW!V1395*24) -> 0 | F44: =IF(NEW!K1395="COMPLETED",0,NEW!W1395*24) -> 0 | G44: =IF(NEW!L1395="COMPLETED",0,NEW!X1395*24) -> 0 | H44: =SUM(E$39:E44) -> 0 | I44: =SUM(F$39:F44) -> 0 | J44: =SUM(G$39:G44) -> 0 | K44: =$B$7+MAX(H44,I44,J44)/$B$5*7 -> 46255 | L44: =IF(ISNUMBER(D44),D44-K44,"") -> -107 | M44: =IF(ISNUMBER(D44),IF(L44<0,"BEHIND",IF(L44<$B$6,"START NOW","ON TRACK")),"no date") -> BEHIND | N44: =IF(ISNUMBER(D44),IF(L44<0,"● LATE",IF(L44<7,"● TIGHT","● OK")),"") -> ● LATE | P44: =IF(ISNUMBER(D44),IF((D44-$B$7)>=7,H44/((D44-$B$7)/7),""),"") | Q44: =IF(ISNUMBER(D44),IF((D44-$B$7)>=7,I44/((D44-$B$7)/7),""),"") | R44: =IF(ISNUMBER(D44),IF((D44-$B$7)>=7,J44/((D44-$B$7)/7),""),"")
A45: =NEW!A1398 -> 1539 | B45: =NEW!C1398 -> PATTI MIKE KLAYKO | C45: =NEW!G1398 -> 46142 | D45: =IF(ISNUMBER(C45),C45-$B$6,"") -> 46141 | E45: =IF(OR(NEW!M1398="COMPLETED",AND(NEW!N1398="COMPLETED",NEW!O1398="COMPLETED")),0,NEW!V1398*24) -> 0 | F45: =IF(NEW!K1398="COMPLETED",0,NEW!W1398*24) -> 0 | G45: =IF(NEW!L1398="COMPLETED",0,NEW!X1398*24) -> 0 | H45: =SUM(E$39:E45) -> 0 | I45: =SUM(F$39:F45) -> 0 | J45: =SUM(G$39:G45) -> 0 | K45: =$B$7+MAX(H45,I45,J45)/$B$5*7 -> 46255 | L45: =IF(ISNUMBER(D45),D45-K45,"") -> -114 | M45: =IF(ISNUMBER(D45),IF(L45<0,"BEHIND",IF(L45<$B$6,"START NOW","ON TRACK")),"no date") -> BEHIND | N45: =IF(ISNUMBER(D45),IF(L45<0,"● LATE",IF(L45<7,"● TIGHT","● OK")),"") -> ● LATE | P45: =IF(ISNUMBER(D45),IF((D45-$B$7)>=7,H45/((D45-$B$7)/7),""),"") | Q45: =IF(ISNUMBER(D45),IF((D45-$B$7)>=7,I45/((D45-$B$7)/7),""),"") | R45: =IF(ISNUMBER(D45),IF((D45-$B$7)>=7,J45/((D45-$B$7)/7),""),"")
...

Sheet CUSHION
A1: {={NEW!A1:A2904, NEW!B1:B2904, NEW!C1:C2904, NEW!F1:F2904, NEW!M1:M2904, NEW!N1:N2904, NEW!O1:O2904, NEW!P1:P2904, NEW!Q1:Q2904, NEW!R1:R2904, NEW!S1:S2904, NEW!V1:V2904}} -> Order Number | B1: Column 2 | C1: Customer Info | D1: Production Deadline | E1: CUSHIONS | F1: CORTE | G1: SEW | H1: FILLING | I1: FABRIC | J1: FOAM | K1: QTY CUSH | L1: Proj. Hrs Cushion
A2: 1572 | B2: ORDER COMPLETED | C2: BETH COHEN | D2: 46203 | E2: COMPLETED | F2: COMPLETED | G2: COMPLETED | H2: COMPLETED | I2: RECEIVED | J2: RECEIVED | K2: 4
A3: 1591 | B3: ORDER COMPLETED | C3: BRIAN BEVERLY BUFFINI | D3: 46203 | E3: COMPLETED | F3: COMPLETED | G3: COMPLETED | H3: COMPLETED | I3: RECEIVED | J3: RECEIVED | K3: 13
A4: 1593 | B4: ORDER COMPLETED | C4: JENNIFER LAABS | D4: 46203 | E4: COMPLETED | F4: COMPLETED | G4: COMPLETED | H4: COMPLETED | I4: RECEIVED | J4: RECEIVED | K4: 16
A5: 1598 | B5: ORDER COMPLETED | C5: WARR-DAN MAYNARD | D5: 46203 | E5: COMPLETED | F5: COMPLETED | G5: COMPLETED | H5: COMPLETED | I5: RECEIVED | J5: SAME-NEED | K5: 25
A6: 1622 | B6: ORDER COMPLETED | C6: MADONA KAKISH | D6: 46203 | E6: COMPLETED | F6: COMPLETED | G6: COMPLETED | H6: COMPLETED | I6: RECEIVED | J6: NOT REQUIRED | K6: 1
A7: 1639 | B7: READY FOR DELIVERY | C7: ROBYN LAUKIE-CHRIS PARK | D7: 46204 | E7: COMPLETED | F7: COMPLETED | G7: COMPLETED | H7: COMPLETED | I7: RECEIVED | J7: RECEIVED | K7: 1
A8: 1677 | B8: READY FOR DELIVERY | C8: TONY KURTH | D8: 46204 | E8: NOT REQUIRED | F8: NOT REQUIRED | G8: NOT REQUIRED | H8: NOT REQUIRED | I8: NOT REQUIRED | J8: NOT REQUIRED | K8: 0 | L8: 0
A9: 1688 | B9: NEW | C9: ERIC WHITTAKER | D9: 46204 | E9: NOT REQUIRED | F9: NOT REQUIRED | G9: NOT REQUIRED | H9: NOT REQUIRED | I9: NOT REQUIRED | J9: NOT REQUIRED | K9: 0 | L9: 0
A10: 1715 | B10: ORDER COMPLETED | C10: JAIME KIM LIMBER | D10: 46204 | E10: NOT REQUIRED | F10: NOT REQUIRED | G10: NOT REQUIRED | H10: NOT REQUIRED | I10: NOT REQUIRED | J10: NOT REQUIRED | K10: 0 | L10: 0
A11: 1627 | B11: ORDER COMPLETED | C11: BRITTANY MCDOWELL | D11: 46204 | E11: NOT REQUIRED | F11: NOT REQUIRED | G11: NOT REQUIRED | H11: NOT REQUIRED | I11: NOT REQUIRED | J11: NOT REQUIRED | K11: 0
A12: 1708 | B12: ORDER COMPLETED | C12: ECHMEYER, KRISTINA & EVAN | D12: 46204 | E12: NOT REQUIRED | F12: NOT REQUIRED | G12: NOT REQUIRED | H12: NOT REQUIRED | I12: NOT REQUIRED | J12: RECEIVED | K12: 0 | L12: 0
A13: 1491 | B13: NEW | C13: KONA RE-DOING-GENCUSH | D13: 46204 | E13: NOT STARTED | F13: NOT STARTED | G13: NOT STARTED | H13: NOT STARTED | I13: NEED | J13: SAME NEED | K13: 20 | L13: 0
A14: 1662 | B14: ORDER COMPLETED | C14: KERYN GERBER | D14: 46253 | E14: NOT REQUIRED | F14: NOT REQUIRED | G14: NOT REQUIRED | H14: NOT REQUIRED | I14: NOT REQUIRED | J14: NOT REQUIRED | K14: 0 | L14: 0
A15: 1663 | B15: ORDER COMPLETED | C15: DAVE MONTZ | D15: 46204 | E15: COMPLETED | F15: COMPLETED | G15: COMPLETED | H15: COMPLETED | I15: RECEIVED | J15: SAME RECEIVED | K15: 1
A16: 1687 | B16: ORDER COMPLETED | C16: JEN BERGMAN | D16: 46204 | E16: COMPLETED | F16: COMPLETED | G16: COMPLETED | H16: COMPLETED | I16: ON STOCK | J16: SAME RECEIVED | K16: 1
A17: 1702 | B17: ORDER COMPLETED | C17: JILL CUTRONE | D17: 46204 | E17: NOT REQUIRED | F17: NOT REQUIRED | G17: NOT REQUIRED | H17: NOT REQUIRED | I17: NOT REQUIRED | J17: NOT REQUIRED
A18: 1703 | B18: ORDER COMPLETED | C18: MIKE CHAFFEUR | D18: 46204 | E18: COMPLETED | F18: COMPLETED | G18: COMPLETED | H18: COMPLETED | I18: NOT REQUIRED | J18: SAME RECEIVED | K18: 2
A19: 1696 | B19: ORDER COMPLETED | C19: LISA FORD | D19: 46205 | E19: COMPLETED | F19: COMPLETED | G19: COMPLETED | H19: COMPLETED | I19: ON STOCK | J19: RECEIVED | K19: 1
A20: 1704 | B20: ORDER COMPLETED | C20: LINDSAY MADERIA WALSH | D20: 46205 | E20: COMPLETED | F20: COMPLETED | G20: COMPLETED | H20: NOT REQUIRED | I20: RECEIVED | J20: NOT REQUIRED | K20: 9
A21: 1638 | B21: ORDER COMPLETED | C21: DIANE GALATI | D21: 46209 | E21: NOT REQUIRED | F21: NOT REQUIRED | G21: NOT REQUIRED | H21: NOT REQUIRED | I21: NOT REQUIRED | J21: NOT REQUIRED | K21: 0
A22: 1605 | B22: ORDER COMPLETED | C22: DEANNE SPRENGER | D22: 46210 | E22: COMPLETED | F22: COMPLETED | G22: COMPLETED | H22: COMPLETED | I22: NOT REQUIRED | J22: RECEIVED | K22: 1
A23: 1643 | B23: ORDER COMPLETED | C23: MEGAN KELLY ADD-ON | D23: 46210 | E23: COMPLETED | F23: COMPLETED | G23: COMPLETED | H23: COMPLETED | I23: IN STOCK | J23: RECEIVED | K23: 5
A24: 1521 | B24: ORDER COMPLETED | C24: RUSH SHOWROOM SWING CUSHION | D24: 46212 | E24: COMPLETED | F24: COMPLETED | G24: COMPLETED | H24: COMPLETED | I24: IN STOCK | J24: RECEIVED | K24: 1
A25: 1502 | B25: ORDER COMPLETED | C25: ROB ROY | D25: 46217 | E25: COMPLETED | F25: COMPLETED | G25: COMPLETED | H25: COMPLETED | I25: RECEIVED | J25: RECEIVED | K25: 18
A26: 1573 | B26: ORDER COMPLETED | C26: SOLANA BEACH SHOWROOM 4-29 | D26: 46217 | E26: COMPLETED | F26: COMPLETED | G26: COMPLETED | H26: COMPLETED | I26: RECEIVED | J26: RECEIVED | K26: 4
A27: 1576 | B27: ORDER COMPLETED | C27: RICHARD AGUILAR | D27: 46217 | E27: COMPLETED | F27: COMPLETED | G27: COMPLETED | H27: COMPLETED | I27: RECEIVED | J27: RECEIVED | K27: 7
A28: 1604 | B28: ORDER COMPLETED | C28: MELANIE SPAHN | D28: 46217 | E28: NOT REQUIRED | F28: NOT REQUIRED | G28: NOT REQUIRED | H28: NOT REQUIRED | I28: NOT REQUIRED | J28: NOT REQUIRED | K28: 0
A29: 1610 | B29: ORDER COMPLETED | C29: PAUL DICOSMO-REDO | D29: 46217 | E29: COMPLETED | F29: COMPLETED | G29: COMPLETED | H29: COMPLETED | I29: RECEIVED | J29: RECEIVED | K29: 2
... A32: 1624 | B32: ORDER COMPLETED | C32: RAQUEL-JASON NORTON | D32: 46217 | E32: NOT REQUIRED | F32: NOT REQUIRED | G32: NOT REQUIRED | H32: NOT REQUIRED | I32: NOT REQUIRED | J32: NOT REQUIRED | K32: 0
A33: 1651 | B33: ORDER COMPLETED | C33: CHAD | D33: 46217 | E33: NOT REQUIRED | F33: NOT REQUIRED | G33: NOT REQUIRED | H33: NOT REQUIRED | I33: NOT REQUIRED | J33: NOT REQUIRED
A34: 1653 | B34: ORDER COMPLETED | C34: CA AMAR TAKHUR | D34: 46217 | E34: NOT REQUIRED | F34: NOT REQUIRED | G34: NOT REQUIRED | H34: NOT REQUIRED | I34: NOT REQUIRED | J34: NOT REQUIRED | K34: 0
A35: 1608 | B35: ORDER COMPLETED | C35: ANDREA SYDENHAM-SERVICE | D35: 46218 | E35: NOT REQUIRED | F35: NOT REQUIRED | G35: NOT REQUIRED | H35: NOT REQUIRED | I35: NOT REQUIRED | J35: NOT REQUIRED | K35: 0
A36: 1617 | B36: ORDER COMPLETED | C36: REDO SHELLY GROTHAUS | D36: 46218 | E36: COMPLETED | F36: COMPLETED | G36: COMPLETED | H36: COMPLETED | I36: IN STOCK | J36: SAME-READY | K36: 2
A37: 1654 | B37: ORDER COMPLETED | C37: CA Edisoon Reynoso | D37: 46218 | E37: NOT REQUIRED | F37: NOT REQUIRED | G37: NOT REQUIRED | H37: NOT REQUIRED | I37: NOT REQUIRED | J37: NOT REQUIRED | K37: 0
A38: 1607 | B38: ORDER COMPLETED | C38: STEPHANIE EVERS-SERVICE | D38: 46219 | E38: NOT REQUIRED | F38: NOT REQUIRED | G38: NOT REQUIRED | H38: NOT REQUIRED | I38: NOT REQUIRED | J38: NOT REQUIRED | K38: 0
A39: 1669 | B39: ORDER COMPLETED | C39: HAMID SHOWROOM 7-17-26 | D39: 46219 | E39: COMPLETED | F39: COMPLETED | G39: COMPLETED | H39: COMPLETED | I39: IN STOCK | J39: RECEIVED | K39: 8
A40: 1546 | B40: ORDER COMPLETED | C40: JIM-CAROL LAUB | D40: 46223 | E40: COMPLETED | F40: COMPLETED | G40: COMPLETED | H40: COMPLETED | I40: RECEIVED | J40: RECEIVED | K40: 19
A41: 1646 | B41: ORDER COMPLETED | C41: JOE REDMOND III | D41: 46225 | E41: COMPLETED | F41: COMPLETED | G41: COMPLETED | H41: COMPLETED | I41: RECEIVED | J41: RECEIVED | K41: 6
A42: 1626 | B42: ORDER COMPLETED | C42: ERIC WHITTAKER | D42: 46226 | E42: COMPLETED | F42: COMPLETED | G42: COMPLETED | H42: COMPLETED | I42: RECEIVED | J42: RECEIVED | K42: 62
...

Sheet ACCESORIOS
A1: {={NEW!A1:A1982, NEW!B1:B1982, NEW!C1:C1982, NEW!F1:F1982, NEW!Y1:Y1982, NEW!Z1:Z1982, NEW!AA1:AA1982, NEW!AB1:AB1982, NEW!AC1:AC1982}} -> Order Number | B1: Column 2 | C1: Customer Info | D1: Production Deadline | E1: Covers | F1: Umbrella | G1: Tenjam/Others | H1: Firepit System | I1: Delivery Address
A2: 1572 | B2: ORDER COMPLETED | C2: BETH COHEN | D2: 46203 | E2: NOT REQUIRED | F2: NOT REQUIRED | G2: NOT REQUIRED | H2: NOT REQUIRED | I2: 10604 Arista Ln, Fountain Hills, AZ 85268, USA
A3: 1591 | B3: ORDER COMPLETED | C3: BRIAN BEVERLY BUFFINI | D3: 46203 | E3: NOT REQUIRED | F3: RECEIVED | G3: NOT REQUIRED | H3: NOT REQUIRED | I3: CALIFORNIA
A4: 1593 | B4: ORDER COMPLETED | C4: JENNIFER LAABS | D4: 46203 | E4: NOT REQUIRED | F4: RECEIVED | G4: NOT REQUIRED | H4: RECEIVED | I4: 484 Halcyon Pl, Bethel Island, CA 94511
A5: 1598 | B5: ORDER COMPLETED | C5: WARR-DAN MAYNARD | D5: 46203 | E5: NOT REQUIRED | F5: NOT REQUIRED | G5: NOT REQUIRED | H5: NOT REQUIRED | I5: 20408 E Cloud Rd, Queen Creek, AZ 85142, USA
A6: 1622 | B6: ORDER COMPLETED | C6: MADONA KAKISH | D6: 46203 | E6: NOT REQUIRED | F6: NOT REQUIRED | G6: NOT REQUIRED | H6: NOT REQUIRED | I6: CALIFORNIA
A7: 1639 | B7: READY FOR DELIVERY | C7: ROBYN LAUKIE-CHRIS PARK | D7: 46204 | E7: NOT REQUIRED | F7: NOT REQUIRED | G7: NOT REQUIRED | H7: NOT REQUIRED | I7: 6352 Arroyo Rd, Cave Creek, AZ 85331, USA
A8: 1677 | B8: READY FOR DELIVERY | C8: TONY KURTH | D8: 46204 | E8: NOT REQUIRED | F8: NOT REQUIRED | G8: NOT REQUIRED | H8: NOT REQUIRED | I8: PICKUP
A9: 1688 | B9: NEW | C9: ERIC WHITTAKER | D9: 46204 | E9: ORDERED | F9: NOT REQUIRED | G9: NOT REQUIRED | H9: NOT REQUIRED | I9: 5400 E Valle Vista Rd #6, Phoenix, AZ 85018
A10: 1715 | B10: ORDER COMPLETED | C10: JAIME KIM LIMBER | D10: 46204 | E10: NOT REQUIRED | F10: NOT REQUIRED | G10: NOT REQUIRED | H10: NOT REQUIRED | I10: 4202 N 58th St PHOENIX AZ 85018
A11: 1627 | B11: ORDER COMPLETED | C11: BRITTANY MCDOWELL | D11: 46204 | E11: RECEIVED | F11: NOT REQUIRED | G11: NOT REQUIRED | H11: NOT REQUIRED | I11: 8404 N 75th St, Scottsdale, AZ 85258, USA
A12: 1708 | B12: ORDER COMPLETED | C12: ECHMEYER, KRISTINA & EVAN | D12: 46204 | E12: NOT REQUIRED | F12: NOT REQUIRED | G12: NOT REQUIRED | H12: NOT REQUIRED | I12: 8321 Baseline Rd, Boulder, CO 80303, USA
A13: 1491 | B13: NEW | C13: KONA RE-DOING-GENCUSH | D13: 46204 | E13: NOT REQUIRED | F13: NOT REQUIRED | G13: NOT REQUIRED | H13: NOT REQUIRED | I13: 72-300 Maheawalu Drive, Kailua-Kona HI 96740
... A70: 1698 | B70: ORDER COMPLETED | C70: OPTIMA 7220 BARSTOOL REUPHOLSTERY | D70: 46244 | E70: NOT REQUIRED | F70: NOT REQUIRED | G70: NOT REQUIRED | H70: NOT REQUIRED | I70: OPTIMA 7220
A71: 1713 | B71: ORDER COMPLETED | C71: OPTIMA 7220 RUSH DOWNSTAIRS | D71: 46244 | E71: NOT REQUIRED | F71: NOT REQUIRED | G71: NOT REQUIRED | H71: NOT REQUIRED
A72: 1657 | B72: ORDER COMPLETED | C72: TIFFANY HERTER | D72: 46245 | E72: NOT REQUIRED | F72: NOT REQUIRED | G72: NOT REQUIRED | H72: NOT REQUIRED | I72: 28119 N. 109th Way
A73: 1684 | B73: ORDER COMPLETED | C73: OPTIMA 7140 FRAMES PHASE I | D73: 46245 | E73: NOT REQUIRED | F73: NOT REQUIRED | G73: NOT REQUIRED | H73: NOT REQUIRED | I73: OPTIMA 7140
A74: 1641 | B74: ORDER COMPLETED | C74: DEBBIE BATTISTA | D74: 46246 | E74: RECEIVED | F74: NOT REQUIRED | G74: NOT REQUIRED | H74: NOT REQUIRED | I74: 1175 E. Copper Hollow Way, Queen Creek, AZ 85740
A75: 1650 | B75: ORDER COMPLETED | C75: CAROL COLOMBO | D75: 46246 | E75: NOT REQUIRED | F75: NOT REQUIRED | G75: NOT REQUIRED | H75: NOT REQUIRED | I75: 5633 N. Royal Circle, Paradise Valley, AZ
A76: 1684 | B76: ORDER COMPLETED | C76: OPTIMA 7140 FRAMES PHASE II | D76: 46248 | E76: NOT REQUIRED | F76: NOT REQUIRED | G76: NOT REQUIRED | H76: NOT REQUIRED | I76: OPTIMA 7140
A77: 1714 | B77: ORDER COMPLETED | C77: CHERYL BURK | D77: 46253 | E77: NOT REQUIRED | F77: NOT REQUIRED | G77: NOT REQUIRED | H77: NOT REQUIRED | I77: SCOTTSDALE SHOWROOM
A78: 1684 | B78: NEW | C78: OPTIMA 7140 PHASE III | D78: 46254 | E78: NOT REQUIRED | F78: NOT REQUIRED | G78: NOT REQUIRED | H78: NOT REQUIRED | I78: OPTIMA 7140
A79: 1635 | B79: ORDER COMPLETED | C79: KATHLEEN WIT | D79: 46254 | E79: NOT REQUIRED | F79: NEED | G79: NOT REQUIRED | H79: NOT REQUIRED | I79: 157 Mozart Ave , CA 92007
A80: 1668 | B80: ORDER COMPLETED | C80: SHARIF & MALIHE | D80: 46254 | E80: NOT REQUIRED | F80: NOT REQUIRED | G80: NOT REQUIRED | H80: NOT REQUIRED | I80: 4832 Fairport Way, San Diego, CA 92130, USA
A81: 1679 | B81: READY FOR DELIVERY | C81: BETH HOFFMAN | D81: 46254 | E81: NOT REQUIRED | F81: NOT REQUIRED | G81: NOT REQUIRED | H81: NOT REQUIRED | I81: 5895 Blazing Star Ln, San Diego, CA 92130, USA
A82: 1690 | B82: ORDER COMPLETED | C82: SOLONA BEACH SHOWROOM | D82: 46254 | E82: NOT REQUIRED | F82: NOT REQUIRED | G82: NOT REQUIRED | H82: NOT REQUIRED | I82: SOLONA BEACH SHOWROOM
A83: 1693 | B83: READY FOR DELIVERY | C83: DAN AMBROSE | D83: 46254 | E83: NOT REQUIRED | F83: NOT REQUIRED | G83: NOT REQUIRED | H83: NOT REQUIRED | I83: 26 9th St HER,OSA BEACH CA
A84: 1578-S | B84: READY FOR DELIVERY | C84: DAN AMBROSE | D84: 46254 | E84: NOT REQUIRED | F84: NOT REQUIRED | G84: NOT REQUIRED | H84: NOT REQUIRED | I84: 26 9th St HER,OSA BEACH CA
A85: 1726 | B85: ORDER COMPLETED | C85: CAROL COLOMBO | D85: 46254 | E85: NOT REQUIRED | F85: NOT REQUIRED | G85: NOT REQUIRED | H85: NOT REQUIRED
A86: 1707 | B86: NEW | C86: SCOTTSDALE SHOWROOM | D86: 46258 | E86: NOT REQUIRED | F86: NOT REQUIRED | G86: NOT REQUIRED | H86: NOT REQUIRED | I86: SCOTTSDALE SHOWROOM
A87: 1673 | B87: NEW | C87: CYNTHIA MANN | D87: 46258 | E87: NOT REQUIRED | F87: NOT REQUIRED | G87: NOT REQUIRED | H87: NOT REQUIRED | I87: 556 W. Moon Valley Drive, Phoenix, AZ
A88: 1682 | B88: READY FOR DELIVERY | C88: JOHN BUTZ | D88: 46259 | E88: NOT REQUIRED | F88: NOT REQUIRED | G88: NOT REQUIRED | H88: NOT REQUIRED | I88: 2926 North Valencia Lane
A89: 1685 | B89: NEW | C89: OPTIMA 7190 FRAMES PHASE I | D89: 46259 | E89: NOT REQUIRED | F89: NOT REQUIRED | G89: NOT REQUIRED | H89: NOT REQUIRED | I89: OPTIMA 7190
A90: 1680 | B90: READY FOR DELIVERY | C90: SHERI RODGERS | D90: 46261 | E90: NOT REQUIRED | F90: NOT REQUIRED | G90: NOT REQUIRED | H90: NOT REQUIRED | I90: 1802 E Phoenix St Payson AZ 85541 / PICK UP FROM SCOTTSDALE SHOWROOM
A91: 1694 | B91: NEW | C91: MIKE GANTZEL | D91: 46261 | E91: NOT REQUIRED | F91: NOT REQUIRED | G91: NOT REQUIRED | H91: NOT REQUIRED | I91: 4099 East Meadowview Dr Gilbert Az 85298
A92: 1644 | B92: READY FOR DELIVERY | C92: CHRISTINE WILSON | D92: 46265 | E92: NOT REQUIRED | F92: NOT REQUIRED | G92: NOT REQUIRED | H92: NOT REQUIRED | I92: 1854 DOWNS ST OCEAN SIDE CA 92054
A93: 1681 | B93: NEW | C93: DAVE KRISTEN ANDERSON | D93: 46265 | E93: NOT REQUIRED | F93: NEED | G93: NOT REQUIRED | H93: NOT REQUIRED | I93: 6343 Clubhouse Dr, Rancho Santa Fe, CA 92091, USA
A94: 1701 | B94: READY FOR DELIVERY | C94: MADONNA KAKISH | D94: 46265 | E94: NOT REQUIRED | F94: NOT REQUIRED | G94: NOT REQUIRED | H94: NOT REQUIRED | I94: 32090 Via Bella Vita TEMECULA CA
A95: 1548 | B95: READY FOR DELIVERY | C95: STEVE-MARGUERITE MORRELL | D95: 46266 | E95: NOT REQUIRED | F95: NOT REQUIRED | G95: NOT REQUIRED | H95: NOT REQUIRED | I95: 16734 N Mountain Parkway, FOUNTAIN HILLS
A96: 1685 | B96: NEW | C96: OPTIMA 7190 FRAMES PHASE II | D96: 46266 | E96: NOT REQUIRED | F96: NOT REQUIRED | G96: NOT REQUIRED | H96: NOT REQUIRED | I96: OPTIMA 7190
...

Sheet CONFIRMACIONES
A1: {={NEW!A1:A1982, NEW!C1:C1982, NEW!B1:B1982, NEW!F1:F1982, NEW!G1:G1982, NEW!H1:H1982, NEW!E1:E1982, NEW!I1:I1982, NEW!AC1:AC1982}} -> Order Number | B1: Customer Info | C1: Column 2 | D1: Production Deadline | E1: Delivery Date | F1: Delivery Conf. | G1: PU / DROP | H1: PU / DROP Confirmed | I1: Delivery Address
A2: 1572 | B2: BETH COHEN | C2: ORDER COMPLETED | D2: 46203 | E2: 46204 | F2: YES | I2: 10604 Arista Ln, Fountain Hills, AZ 85268, USA
A3: 1591 | B3: BRIAN BEVERLY BUFFINI | C3: ORDER COMPLETED | D3: 46203 | E3: 46204 | F3: YES | I3: CALIFORNIA
A4: 1593 | B4: JENNIFER LAABS | C4: ORDER COMPLETED | D4: 46203 | E4: 46205 | F4: YES | I4: 484 Halcyon Pl, Bethel Island, CA 94511
A5: 1598 | B5: WARR-DAN MAYNARD | C5: ORDER COMPLETED | D5: 46203 | E5: 46203 | G5: 46203 | I5: 20408 E Cloud Rd, Queen Creek, AZ 85142, USA
A6: 1622 | B6: MADONA KAKISH | C6: ORDER COMPLETED | D6: 46203 | E6: 46205 | F6: YES | I6: CALIFORNIA
A7: 1639 | B7: ROBYN LAUKIE-CHRIS PARK | C7: READY FOR DELIVERY | D7: 46204 | E7: 46204 | F7: NO | H7: NA | I7: 6352 Arroyo Rd, Cave Creek, AZ 85331, USA
A8: 1677 | B8: TONY KURTH | C8: READY FOR DELIVERY | D8: 46204 | E8: 46204 | F8: NO | H8: NA | I8: PICKUP
A9: 1688 | B9: ERIC WHITTAKER | C9: NEW | D9: 46204 | E9: 46204 | F9: NO | H9: NA | I9: 5400 E Valle Vista Rd #6, Phoenix, AZ 85018
A10: 1715 | B10: JAIME KIM LIMBER | C10: ORDER COMPLETED | D10: 46204 | E10: 46246 | F10: YES | G10: 46246 | H10: YES | I10: 4202 N 58th St PHOENIX AZ 85018
A11: 1627 | B11: BRITTANY MCDOWELL | C11: ORDER COMPLETED | D11: 46204 | E11: 46204 | F11: YES | G11: 46233 | H11: YES | I11: 8404 N 75th St, Scottsdale, AZ 85258, USA
A12: 1708 | B12: ECHMEYER, KRISTINA & EVAN | C12: ORDER COMPLETED | D12: 46204 | E12: 46204 | F12: NO | H12: NA | I12: 8321 Baseline Rd, Boulder, CO 80303, USA
A13: 1491 | B13: KONA RE-DOING-GENCUSH | C13: NEW | D13: 46204 | E13: 46204 | F13: NO | H13: NA | I13: 72-300 Maheawalu Drive, Kailua-Kona HI 96740
A14: 1662 | B14: KERYN GERBER | C14: ORDER COMPLETED | D14: 46253 | E14: 46253 | F14: YES | G14: 46233 | H14: YES | I14: 4103 n 64th pl, Scottsdale, Arizona 85251
A15: 1663 | B15: DAVE MONTZ | C15: ORDER COMPLETED | D15: 46204 | E15: 46204 | F15: NO | G15: 46212 | H15: YES | I15: DROP & PICK AT FACTORY
A16: 1687 | B16: JEN BERGMAN | C16: ORDER COMPLETED | D16: 46204 | E16: 46204 | F16: NO | H16: NA | I16: 3386 S Stuart Ave, Gilbert, AZ 85297, USA
A17: 1702 | B17: JILL CUTRONE | C17: ORDER COMPLETED | D17: 46204 | E17: 46204 | F17: NO | H17: NA | I17: 14762 N Strong Stone Dr, Oro Valley, AZ 85755, USA
A18: 1703 | B18: MIKE CHAFFEUR | C18: ORDER COMPLETED | D18: 46204 | E18: 46204 | F18: NO | H18: NA | I18: 9431 N Solitude Canyon Fountain Hills AZ 85268
A19: 1696 | B19: LISA FORD | C19: ORDER COMPLETED | D19: 46205 | E19: 46205 | F19: YES | H19: NA | I19: COLORADO
A20: 1704 | B20: LINDSAY MADERIA WALSH | C20: ORDER COMPLETED | D20: 46205 | E20: 46205 | F20: YES | H20: NA | I20: 2055 Bear Hollow Dr, Park City, UT 84098, USA
A21: 1638 | B21: DIANE GALATI | C21: ORDER COMPLETED | D21: 46209 | E21: 46210 | F21: YES | I21: 4939 E Horseshoe Rd, Paradise Valley, AZ 85253, USA
A22: 1605 | B22: DEANNE SPRENGER | C22: ORDER COMPLETED | D22: 46210 | E22: 46210 | F22: YES | G22: 46212 | H22: YES | I22: 13452 E Desert Trail Scottsdale, AZ 85259
A23: 1643 | B23: MEGAN KELLY ADD-ON | C23: ORDER COMPLETED | D23: 46210 | E23: 46211 | F23: YES | H23: NA | I23: 10276 White Birch St, Presque Isle, MI 49777, USA
A24: 1521 | B24: RUSH SHOWROOM SWING CUSHION | C24: ORDER COMPLETED | D24: 46212 | E24: 46212 | F24: YES | H24: NA | I24: 15037 N Scottsdale Rd Ste 120, Scottsdale, AZ 85254
A25: 1502 | B25: ROB ROY | C25: ORDER COMPLETED | D25: 46217 | E25: 46218 | F25: YES | H25: NA | I25: CALIFORNIA
A26: 1573 | B26: SOLANA BEACH SHOWROOM 4-29 | C26: ORDER COMPLETED | D26: 46217 | E26: 46218 | F26: YES | H26: NA | I26: CALIFORNIA
A27: 1576 | B27: RICHARD AGUILAR | C27: ORDER COMPLETED | D27: 46217 | E27: 46218 | F27: YES | H27: NA | I27: 5435 Calumet Ave, LA JOLLA, CA
A28: 1604 | B28: MELANIE SPAHN | C28: ORDER COMPLETED | D28: 46217 | E28: 46218 | F28: YES | G28: 46218 | H28: YES | I28: 8621 E Clarendon Ave, Scottsdale, AZ 85251, USA
A29: 1610 | B29: PAUL DICOSMO-REDO | C29: ORDER COMPLETED | D29: 46217 | E29: 46217 | F29: YES | G29: 46211 | H29: YES | I29: 18724 E Chandler Heights Rd, Queen Creek, AZ 85142, USA
A30: 1613 | B30: RAQUEL-JASON NORTON | C30: ORDER COMPLETED | D30: 46217 | E30: 46218 | F30: YES | H30: NA | I30: CALIFORNIA
A31: 1614 | B31: BETH HOFFMAN | C31: ORDER COMPLETED | D31: 46217 | E31: 46218 | F31: YES | H31: NA | I31: CALIFORNIA
A32: 1624 | B32: RAQUEL-JASON NORTON | C32: ORDER COMPLETED | D32: 46217 | E32: 46218 | F32: YES | H32: NA | I32: 1468 Rimcrest Ct, BONITA CA 91902
A33: 1651 | B33: CHAD | C33: ORDER COMPLETED | D33: 46217 | E33: 46218 | F33: YES | G33: 46212 | H33: YES | I33: 13260 N 83rd Pl SCOTTSDALE AZ 85260
A34: 1653 | B34: CA AMAR TAKHUR | C34: ORDER COMPLETED | D34: 46217 | E34: 46219 | F34: YES | H34: NA | I34: 304 N Sierra Ave, Solana Beach, CA 92075
A35: 1608 | B35: ANDREA SYDENHAM-SERVICE | C35: ORDER COMPLETED | D35: 46218 | E35: 46219 | F35: YES | G35: 46202 | H35: YES | I35: 26814 Boulder Ln, Scottsdale, AZ 85255, USA
A36: 1617 | B36: REDO SHELLY GROTHAUS | C36: ORDER COMPLETED | D36: 46218 | E36: 46219 | F36: YES | G36: 46202 | H36: YES | I36: 10801 E Happy Valley Rd, Scottsdale, AZ 85255, USA
A37: 1654 | B37: CA Edisoon Reynoso | C37: ORDER COMPLETED | D37: 46218 | E37: 46219 | F37: YES | H37: NA | I37: 5986 Greensview Ct, RANCHO SANTA FE, CA 92067
A38: 1607 | B38: STEPHANIE EVERS-SERVICE | C38: ORDER COMPLETED | D38: 46219 | E38: 46219 | F38: YES | G38: 46204 | H38: YES | I38: 5736 E Lowden Rd, Cave Creek, AZ 85331, USA
A39: 1669 | B39: HAMID SHOWROOM 7-17-26 | C39: ORDER COMPLETED | D39: 46219 | E39: 46219 | F39: YES | H39: NA | I39: SCOTTSDALE SHOWROOM
A40: 1546 | B40: JIM-CAROL LAUB | C40: ORDER COMPLETED | D40: 46223 | E40: 46225 | F40: YES | H40: NA | I40: 8745 North Lookout Lane, Park City, UT
...

Sheet Lookup
A1: ORDER QUICK LOOKUP
A3: Look up Order #: | B3: 1563
A5: Customer | B5: {=IF($B$3="","",IFNA(_xlfn.XLOOKUP($B$3,NEW!$A:$A,NEW!$C:$C),"Not found"))} -> JIM BUTLER
A6: Order Status | B6: {=IF($B$3="","",IFNA(_xlfn.XLOOKUP($B$3,NEW!$A:$A,NEW!$B:$B),"Not found"))} -> ORDER COMPLETED
A7: PDF / Type | B7: {=IF($B$3="","",IFNA(_xlfn.XLOOKUP($B$3,NEW!$A:$A,NEW!$D:$D),"Not found"))} -> RESIDENTIAL
